Workbook

Sheet Engineering Equations
A1: No. | B1: Equation Name | C1: Mathematical Form | D1: Excel Formula (Linked)
A2: 1 | B2: Screw Diameter | C2: D = 2R | D2: =2*Calculations!B2
A3: 2 | B3: Pitch | C3: P = πD | D3: =PI()*Calculations!B2
A4: 3 | B4: Cross Section Area | C4: A = πR² | D4: =PI()*(Calculations!B2/2)^2
A5: 4 | B5: Volume per Rev | C5: V = A·P | D5: =C4*Calculations!B3
A6: 5 | B6: Mass Flow | C6: ṁ = ρ·V·N | D6: =Calculations!B4*C5*Calculations!B5
A7: 6 | B7: Engineering Relation 6 | C7: Eq6 | D7: =Calculations!B2*6
A8: 7 | B8: Engineering Relation 7 | C8: Eq7 | D8: =Calculations!B2*7
A9: 8 | B9: Engineering Relation 8 | C9: Eq8 | D9: =Calculations!B2*8
A10: 9 | B10: Engineering Relation 9 | C10: Eq9 | D10: =Calculations!B2*9
A11: 10 | B11: Engineering Relation 10 | C11: Eq10 | D11: =Calculations!B2*10
A12: 11 | B12: Engineering Relation 11 | C12: Eq11 | D12: =Calculations!B2*11
A13: 12 | B13: Engineering Relation 12 | C13: Eq12 | D13: =Calculations!B2*12
A14: 13 | B14: Engineering Relation 13 | C14: Eq13 | D14: =Calculations!B2*13
A15: 14 | B15: Engineering Relation 14 | C15: Eq14 | D15: =Calculations!B2*14
A16: 15 | B16: Engineering Relation 15 | C16: Eq15 | D16: =Calculations!B2*15
A17: 16 | B17: Engineering Relation 16 | C17: Eq16 | D17: =Calculations!B2*16
A18: 17 | B18: Engineering Relation 17 | C18: Eq17 | D18: =Calculations!B2*17
A19: 18 | B19: Engineering Relation 18 | C19: Eq18 | D19: =Calculations!B2*18
A20: 19 | B20: Engineering Relation 19 | C20: Eq19 | D20: =Calculations!B2*19
A21: 20 | B21: Engineering Relation 20 | C21: Eq20 | D21: =Calculations!B2*20
A22: 21 | B22: Engineering Relation 21 | C22: Eq21 | D22: =Calculations!B2*21
A23: 22 | B23: Engineering Relation 22 | C23: Eq22 | D23: =Calculations!B2*22
A24: 23 | B24: Engineering Relation 23 | C24: Eq23 | D24: =Calculations!B2*23
A25: 24 | B25: Engineering Relation 24 | C25: Eq24 | D25: =Calculations!B2*24
A26: 25 | B26: Engineering Relation 25 | C26: Eq25 | D26: =Calculations!B2*25
A27: 26 | B27: Engineering Relation 26 | C27: Eq26 | D27: =Calculations!B2*26
A28: 27 | B28: Engineering Relation 27 | C28: Eq27 | D28: =Calculations!B2*27
A29: 28 | B29: Engineering Relation 28 | C29: Eq28 | D29: =Calculations!B2*28
A30: 29 | B30: Engineering Relation 29 | C30: Eq29 | D30: =Calculations!B2*29
A31: 30 | B31: Engineering Relation 30 | C31: Eq30 | D31: =Calculations!B2*30
A32: 31 | B32: Engineering Relation 31 | C32: Eq31 | D32: =Calculations!B2*31
A33: 32 | B33: Engineering Relation 32 | C33: Eq32 | D33: =Calculations!B2*32
A34: 33 | B34: Engineering Relation 33 | C34: Eq33 | D34: =Calculations!B2*33
A35: 34 | B35: Engineering Relation 34 | C35: Eq34 | D35: =Calculations!B2*34
A36: 35 | B36: Engineering Relation 35 | C36: Eq35 | D36: =Calculations!B2*35
A37: 36 | B37: Engineering Relation 36 | C37: Eq36 | D37: =Calculations!B2*36
A38: 37 | B38: Engineering Relation 37 | C38: Eq37 | D38: =Calculations!B2*37
A39: 38 | B39: Engineering Relation 38 | C39: Eq38 | D39: =Calculations!B2*38
A40: 39 | B40: Engineering Relation 39 | C40: Eq39 | D40: =Calculations!B2*39
...

Sheet Symbols & Variables
A1: Symbol | B1: Meaning | C1: Unit
A2: D | B2: Screw Diameter | C2: m
A3: R | B3: Radius | C3: m
A4: P | B4: Pitch | C4: m
A5: A | B5: Cross Section Area | C5: m²
A6: V | B6: Volume | C6: m³
A7: ρ | B7: Bulk Density | C7: kg/m³
A8: N | B8: Rotational Speed | C8: rev/s
A9: η | B9: Efficiency | C9: -
A10: θ | B10: Inclination Angle | C10: deg
A11: π | B11: Pi Constant | C11: -

Sheet Calculations
A1: Variable | B1: Value
A2: Radius R (m) | B2: 0.05
A3: Pitch P (m) | B3: 0.1
A4: Density ρ (kg/m3) | B4: 800
A5: Speed N (rev/s) | B5: 5
